Workbook

Sheet Introduction and country list
A1: Introduction: SCORE2-Diabetes 10-year CVD risk calculator.
A2: 10-year risk can be estimated by entering individual values into the calculator sheet. Drop down menus are present for Risk region, sex and smoking status; otherwise numerical values must be entred in the units given for each risk predictor. The relevant risk region for each country of residence can be obtained in the following Table
A8: Low risk region | B8: Belgium
B9: Denmark
B10: France
B11: Israel
B12: Luxembourg
B13: Netherlands
B14: Norway
B15: Spain
B16: Switzerland
B17: United Kingdom
A18: Moderate risk region | B18: Austria
B19: Cyprus
B20: Finland
B21: Germany
B22: Greece
B23: Iceland
B24: Ireland
B25: Italy
B26: Malta
B27: Portugal
B28: San Marino
B29: Slovenia
B30: Sweden
A31: High risk region | B31: Albania
B32: Bosnia and Herzegovina
B33: Croatia
B34: Czech Republic
B35: Estonia
B36: Hungary
B37: Kazakhstan
B38: Poland
B39: Slovakia
B40: Turkey
A41: Very high risk region | B41: Algeria
B42: Armenia
B43: Azerbaijan
B44: Belarus
B45: Bulgaria
...

Sheet calculator
A1: Risk Predictor | B1: Value (please enter values below)
A2: Risk Region | B2: Moderate risk region
A3: Sex | B3: Male
A4: Age (yrs) | B4: 53
A5: Diabetes age at diagnosis (yrs) | B5: 30
A6: Current smoker | B6: yes
A7: SBP (mm Hg) | B7: 110
A8: Total cholesterol (mmol/L) | B8: 4.5
A9: HDL cholesterol (mmol/L) | B9: 1.4
A10: HbA1c (mmol/mol) | B10: 55
A11: eGFR (ml/min/1.73m^2) | B11: 95
A13: 10-year CVD risk estimate | B13: =IF(AND(B3="Male",B2="Low risk region"),values!D14,IF(AND(B3="Male",B2="Moderate risk region"),values!D15,IF(AND(B3="Male",B2="High risk region"),values!D16,IF(AND(B3="Male",B2="Very high risk region"),values!D17,IF(AND(B3="Female",B2="Low risk region"),values!H14,IF(AND(B3="Female",B2="Moderate risk region"),values!H15,IF(AND(B3="Female",B2="High risk region"),values!H16, values!H17))))))) -> 13.116445

Sheet values
B1: value | C1: centred val | D1: points men | E1: Men | H1: points women | I1: Women
E2: B men | F2: B fac*age | G2: B squared | I2: B women | J2: B fac*age | K2: B squared
A3: Diabetes (yes vs. no) | E3: 0.6457 | F3: -0.0983 | I3: 0.8096 | J3: -0.1272
A4: Age (yrs) | B4: =calculator!B4 -> 53 | C4: =(B4-60)/5 -> -1.4 | D4: =E3+C4*F3+C4*E4 -> 0.0318 | E4: 0.5368 | H4: =I3+C4*J3+C4*I4 -> 0.06032 | I4: 0.6624
A5: Diabetes age at diagnosis (yrs) | B5: =calculator!B5 -> 30 | C5: =(B5-50)/5 -> -4 | D5: =C5*E5 -> 0.3992 | E5: -0.0998 | F5: 0 | H5: =C5*I5 -> 0.472 | I5: -0.118
A6: smoking current | B6: =calculator!B6 -> yes | C6: =B6 -> yes | D6: =IF(B6="yes", E6+C4*F6, 0) -> 0.57148 | E6: 0.4774 | F6: -0.0672 | H6: =IF(C6="yes", I6+C4*J6, 0) -> 0.77098 | I6: 0.6139 | J6: -0.1122
A7: SBP (mm Hg) | B7: =calculator!B7 -> 110 | C7: =(B7-120)/20 -> -0.5 | D7: =C7*E7+$C$4*C7*F7 -> -0.08486 | E7: 0.1322 | F7: -0.0268 | H7: =C7*I7+$C$4*C7*J7 -> -0.08274 | I7: 0.1421 | J7: -0.0167
A8: Total cholesterol (mmol/L) | B8: =calculator!B8 -> 4.5 | C8: =(B8-6) -> -1.5 | D8: =C8*E8+$C$4*C8*F8 -> -0.20331 | E8: 0.1102 | F8: -0.0181 | H8: =C8*I8+$C$4*C8*J8 -> -0.21105 | I8: 0.1127 | J8: -0.02
A9: HDL cholesterol (mmol/L) | B9: =calculator!B9 -> 1.4 | C9: =(B9-1.3)/0.5 -> 0.2 | D9: =C9*E9+$C$4*C9*F9 -> -0.0244 | E9: -0.1087 | F9: 0.0095 | H9: =C9*I9+$C$4*C9*J9 -> -0.036568 | I9: -0.1568 | J9: 0.0186
A10: HbA1c (mmol/mol) | B10: =calculator!B10 -> 55 | C10: =(B10-31)/9.34 -> 2.5695931 | D10: =C10*E10+$C$4*C10*F10 -> 0.29360171 | E10: 0.0955 | F10: -0.0134 | H10: =C10*I10+$C$4*C10*J10 -> 0.37192291 | I10: 0.1173 | J10: -0.0196
A11: Ln eGFR (ml/min/1.73m^2) | B11: =calculator!B11 -> 95 | C11: =(LN(B11)-4.5)/0.15 -> 0.35917928 | D11: =C11*E11+C4*C11*F11+C11*C11*G11 -> -0.026262025 | E11: -0.0591 | F11: 0.0115 | G11: 0.0058 | H11: =C11*I11+C4*C11*J11+C11*C11*K11 -> -0.030685795 | I11: -0.064 | J11: 0.0169 | K11: 0.0062
A12: LP | D12: =SUM(D4:D11) -> 0.95724969 | H12: =SUM(H4:H11) -> 1.3141791
A13: Risk unclaibrated | D13: =1-0.9605^EXP(D12) -> 0.099644568 | H13: =1-0.9776^EXP(H12) -> 0.080857254
A14: risk low risk region | D14: =100*(1-EXP(-EXP(-0.5699+0.7476*LN(-LN(1-D13))))) -> 9.9553916 | H14: =100*(1-EXP(-EXP(-0.738+0.7019*LN(-LN(1-H13))))) -> 8.080021
A15: risk moderate | D15: =100*(1-EXP(-EXP(-0.1565+0.8009*LN(-LN(1-D13))))) -> 13.116445 | H15: =100*(1-EXP(-EXP(-0.3143+0.7701*LN(-LN(1-H13))))) -> 10.302442
A16: risk high | D16: =100*(1-EXP(-EXP(0.3207+0.936*LN(-LN(1-D13))))) -> 15.388567 | H16: =100*(1-EXP(-EXP(0.571+0.9369*LN(-LN(1-H13))))) -> 16.007637
A17: risk very high | D17: =100*(1-EXP(-EXP(0.5836+0.8294*LN(-LN(1-D13))))) -> 24.147742 | H17: =100*(1-EXP(-EXP(0.9412+0.8329*LN(-LN(1-H13))))) -> 27.869448
